{
    "color": "D7E3D4",
    "localizedname": "Atomic Reconstructor",
    "registryname": "atomic_reconstructor",
    "parts": [
        {
            "elements": [
                "modularmachinery:blockcasing@4"
            ],
            "x": 1,
            "y": -1,
            "z": 0
        },
        {
            "elements": [
                "modularmachinery:blockcasing@4"
            ],
            "x": 0,
            "y": -1,
            "z": 0
        },
        {
            "elements": [
                "modularmachinery:blockcasing@4"
            ],
            "x": -1,
            "y": -1,
            "z": 0
        },
        {
            "elements": [
                "modularmachinery:blockcasing@4"
            ],
            "x": -2,
            "y": -1,
            "z": 0
        },
        {
            "elements": [
                "modularmachinery:blockcasing@5"
            ],
            "x": 1,
            "y": -1,
            "z": 1
        },
        {
            "elements": [
                "modularmachinery:blockcasing@4"
            ],
            "x": 0,
            "y": -1,
            "z": 1
        },
        {
            "elements": [
                "modularmachinery:blockcasing@4"
            ],
            "x": -1,
            "y": -1,
            "z": 1
        },
        {
            "elements": [
                "modularmachinery:blockcasing@4"
            ],
            "x": -2,
            "y": -1,
            "z": 1
        },
        {
            "elements": [
                "modularmachinery:blockoutputbus"
            ],
            "x": -3,
            "y": -1,
            "z": 1
        },
        {
            "elements": [
                "modularmachinery:blockcasing@4"
            ],
            "x": 1,
            "y": -1,
            "z": 2
        },
        {
            "elements": [
                "modularmachinery:blockcasing@4"
            ],
            "x": 0,
            "y": -1,
            "z": 2
        },
        {
            "elements": [
                "modularmachinery:blockcasing@4"
            ],
            "x": -1,
            "y": -1,
            "z": 2
        },
        {
            "elements": [
                "modularmachinery:blockcasing@4"
            ],
            "x": -2,
            "y": -1,
            "z": 2
        },
        {
            "elements": [
                "modularmachinery:blockcasing@5"
            ],
            "x": 1,
            "y": 0,
            "z": 0
        },
        {
            "elements": [
                "modularmachinery:blockcasing@2"
            ],
            "x": -1,
            "y": 0,
            "z": 0
        },
        {
            "elements": [
                "modularmachinery:blockcasing@4"
            ],
            "x": -2,
            "y": 0,
            "z": 0
        },
        {
            "elements": [
                "modularmachinery:blockenergyinputhatch"
            ],
            "x": 2,
            "y": 0,
            "z": 1
        },
        {
            "elements": [
                "modularmachinery:blockcasing@5"
            ],
            "x": 1,
            "y": 0,
            "z": 1
        },
        {
            "elements": [
                "actuallyadditions:block_atomic_reconstructor"
            ],
            "x": 0,
            "y": 0,
            "z": 1
        },
        {
            "elements": [
                "chisel:antiblock@2"
            ],
            "x": -2,
            "y": 0,
            "z": 1
        },
        {
            "elements": [
                "modularmachinery:blockcasing@5"
            ],
            "x": 1,
            "y": 0,
            "z": 2
        },
        {
            "elements": [
                "modularmachinery:blockcasing@4"
            ],
            "x": 0,
            "y": 0,
            "z": 2
        },
        {
            "elements": [
                "modularmachinery:blockcasing@2"
            ],
            "x": -1,
            "y": 0,
            "z": 2
        },
        {
            "elements": [
                "modularmachinery:blockcasing@4"
            ],
            "x": -2,
            "y": 0,
            "z": 2
        },
        {
            "elements": [
                "modularmachinery:blockcasing@4"
            ],
            "x": 1,
            "y": 1,
            "z": 0
        },
        {
            "elements": [
                "modularmachinery:blockcasing@4"
            ],
            "x": 0,
            "y": 1,
            "z": 0
        },
        {
            "elements": [
                "modularmachinery:blockcasing@4"
            ],
            "x": -1,
            "y": 1,
            "z": 0
        },
        {
            "elements": [
                "modularmachinery:blockcasing@4"
            ],
            "x": -2,
            "y": 1,
            "z": 0
        },
        {
            "elements": [
                "modularmachinery:blockcasing@5"
            ],
            "x": 1,
            "y": 1,
            "z": 1
        },
        {
            "elements": [
                "modularmachinery:blockcasing@4"
            ],
            "x": 0,
            "y": 1,
            "z": 1
        },
        {
            "elements": [
                "modularmachinery:blockcasing@4"
            ],
            "x": -2,
            "y": 1,
            "z": 1
        },
        {
            "elements": [
                "modularmachinery:blockcasing@4"
            ],
            "x": 1,
            "y": 1,
            "z": 2
        },
        {
            "elements": [
                "modularmachinery:blockcasing@4"
            ],
            "x": 0,
            "y": 1,
            "z": 2
        },
        {
            "elements": [
                "modularmachinery:blockcasing@4"
            ],
            "x": -1,
            "y": 1,
            "z": 2
        },
        {
            "elements": [
                "modularmachinery:blockcasing@4"
            ],
            "x": -2,
            "y": 1,
            "z": 2
        },
        {
            "elements": [
                "modularmachinery:blockcasing@5"
            ],
            "x": 1,
            "y": 2,
            "z": 1
        },
        {
            "elements": [
                "modularmachinery:blockcasing@5"
            ],
            "x": 0,
            "y": 2,
            "z": 1
        },
        {
            "elements": [
                "modularmachinery:blockinputbus"
            ],
            "x": -1,
            "y": 2,
            "z": 1
        }
    ]
}